[ { "title": "docker 설치 시 wsl2 에러", "url": "/posts/docker-%EC%84%A4%EC%B9%98-%EC%8B%9C-wsl2-%EC%97%90%EB%9F%AC/", "categories": "Error", "tags": "wsl2, docker", "date": "2022-07-26 02:22:00 +0900", "snippet": "Error 윈도우에 docker를 설치할 시 다음과 같은 창이 떴다.Error 해결 링크된 주소로 들어가 4단계인 Linux 커널 업데이트 패키지를 다운 후 팝업 창의 Restart를 눌렀더니 해결되었다." }, { "title": "UNABLE_TO_VERIFY_LEAF_SIGNATURE", "url": "/posts/UNABLE_TO_VERIFY_LEAF_SIGNATURE/", "categories": "Error", "tags": "npm", "date": "2022-07-26 02:21:00 +0900", "snippet": "Error react 설치 중 다음과 같은 명령어를 실행했을 때 에러 발생npm install -g create-react-appError 해결 ssl로 인해 설치가 막힌듯 하다. 다음 명령어를 사용하여 ssl 사용을 하지 않도록 변경한다.npm config set strict-ssl false참고 사이트UNABLE_TO_VERIFY_LEAF_SIGNATURE 에러 발생시" }, { "title": "JavaScript 객체", "url": "/posts/JavaScript-%EA%B0%9D%EC%B2%B4/", "categories": "Language, JavaScript", "tags": "JavaScript, 객체", "date": "2022-07-25 21:12:00 +0900", "snippet": "JS의 객체 js에서 객체는 다음과 같이 코드를 작성할 수 있다. const person = { name : &#39;홍길동&#39;, age : 20 }; 객체의 값은 다음과 같이 불러 올 수 있다. console.log(person.name); 한번 이 객체를 다른 함수에서 사용해보자 const person = { name : &#39;홍길동&#39;, age : 20 }; function print(p1){ const introduce = `제 이름은 ${p1.name}입니다.`; console.log(introduce); } print(person); 객체 비구조화 할당 객체화는 여러가지를 하나로 묶는 packing 느낌이였다면 객체 비구조화는 객체를 풀어버리는 것이다. const person = { name : &#39;홍길동&#39;, age : 20 }; function print(p1){ const {name, age} = p1; const introduce = `제 이름은 ${name}입니다.`; console.log(introduce); } print(person); 객체에서 값들을 추출해서 새로운 상수로 선언해준다. parameter 자체를 객체 비구조화로 사용할 수도 있다. const person = { name : &#39;홍길동&#39;, age : 20 }; function print({name,age}){ const introduce = `제 이름은 ${name}입니다.`; console.log(introduce); } print(person); 객체 안에 함수 객체 안에는 함수도 선언할 수 있다. const person = { name : &#39;홍길동&#39;, age : 20, hi: function hi(){ console.log(&#39;내 이름은 &#39; + this.name + &#39; 이야&#39;); } }; person.hi(); this는 객체인 자기 자신을 뜻한다. 주의할 점 : 함수를 function이 아닌 화살표 함수로 선언할 수 있지만 this가 들어가는 경우는 자기 자신을 참조할 수 없어 에러가 발생한다. Getter와 Setter 다음과 같이 getter와 setter함수를 만들 수 있다. const numbers = { _a: 1, _b: 2, sum: 3, calculate() { console.log(&#39;calculate&#39;); this.sum = this._a + this._b; }, get a() { return this._a; }, get b() { return this._b; }, set a(value) { console.log(&#39;a가 바뀝니다.&#39;); this._a = value; this.calculate(); }, set b(value) { console.log(&#39;b가 바뀝니다.&#39;); this._b = value; this.calculate(); } }; console.log(numbers.sum); // 3 출력 numbers.a = 5; // _a를 5로 설정 numbers.b = 7; // _b를 7로 설정, sum 12로 설정 numbers.a = 9; // _a를 9로 설정, sum 16으로 설정 console.log(numbers.sum); // 16 출력 참고 사이트 벨로퍼트와 함께하는 모던 자바스크립트 " }, { "title": "RuntimeError: CUDA error: device-side assert triggered", "url": "/posts/RuntimeError-CUDA-error-device-side-assert-triggered/", "categories": "Error", "tags": "CUDA, colab, kobert, nlp", "date": "2022-04-07 19:07:00 +0900", "snippet": "Error kobert를 실행시키던 도중 다음과 같은 에러가 발생하였다. Error 해결 이런 경우 보통 차원 수가 맞지 않아 발생하는 에러라고 한다. 아니나 다를까 9개로 분류를 해야하는데 3으로 되어 있어 고쳤더니 에러가 바로 해결되었다.참고 사이트[PyTorch 오류 해결] RuntimeError: CUDA error: device-side assert triggered" }, { "title": "AttributeError: Can&#39;t get attribute &#39;BERTClassifier&#39; on module &#39;__main__&#39; from &#39;path&#39;", "url": "/posts/AttributeError-Can't-get-attribute-'BERTClassifier'-on-module-'__main__'-from-'path'/", "categories": "Error", "tags": "flask, kobert, torch.load", "date": "2022-04-07 05:45:00 +0900", "snippet": "Error Flask에서 model을 불러오려고 하니 다음과 같이 error가 발생하였다. sentimentModel = torch.load(&#39;./model.pt&#39;, map_location=&#39;cpu&#39;) Error 해결 torch.save(model, &#39;model.pt&#39;)로 저장하여 model 전체를 불러오려고 하니 어떤 모델인지 정의 되어 있지 않아 에러가 나는거 같았다. torch.save(model.state_dict(), &#39;model.pt&#39;)로 저장한 후 모델을 정의하고 정의된 모델에 load를 하여 가중치와 편향을 부여하는 방법으로 해결하였다. model = BERTClassifier(bertmodel, dr_rate=0.5).to(device) model.load_state_dict(torch.load(&#39;model_state_dict.pt&#39;, map_location=&#39;cpu&#39;)) 참고 사이트[Pytorch] 모델 저장 방법, 그리고 전체 저장과 state_dict 저장의 차이" }, { "title": "The dependencies of some of the beans in the application context form a cycle:", "url": "/posts/The-dependencies-of-some-of-the-beans-in-the-application-context-form-a-cycle/", "categories": "Error", "tags": "spring", "date": "2022-04-07 05:43:00 +0900", "snippet": "Error rest template을 다음과 같이 사용했을 때 Error가 발생했다. service 인터페이스 package kr.pe.playdata.service; import java.util.concurrent.CompletableFuture; public interface RecommandService { /* 관광지 추천 서비스 인터페이스 */ public CompletableFuture&amp;lt;String&amp;gt; recommand(String keywords); } service 구현 package kr.pe.playdata.service.impl; import kr.pe.playdata.service.RecommandService; import org.springframework.beans.factory.annotation.Autowired; import org.springframework.scheduling.annotation.Async; import org.springframework.stereotype.Service; import org.springframework.util.LinkedMultiValueMap; import org.springframework.util.MultiValueMap; import org.springframework.web.client.RestTemplate; import java.util.concurrent.CompletableFuture; @Service public class RecommandServiceImpl implements RecommandService { /* 관광지를 추천해주는 서비스 구현체 */ @Autowired private RestTemplate restTemplate; @Bean public RestTemplate restTemplate(){ return new RestTemplate(); } @Async(&quot;asyncExecutor&quot;) public CompletableFuture&amp;lt;String&amp;gt; recommand(String keywords){ String url = &quot;http://127.0.0.1:5000/recommand&quot;; MultiValueMap&amp;lt;String, String&amp;gt; param = new LinkedMultiValueMap&amp;lt;String, String&amp;gt;(); param.add(&quot;keywords&quot;,keywords); String sb = restTemplate.postForObject(url, param, String.class); return CompletableFuture.completedFuture(sb); } } Error 발생 Error 해결 RestTemplate Config를 만들어 RestTemplate을 미리 Bean에 등록하였다. package kr.pe.playdata.config; import org.springframework.context.annotation.Bean; import org.springframework.context.annotation.Configuration; import org.springframework.web.client.RestTemplate; @Configuration public class RestTemplateConfig { /* rest Config */ @Bean public RestTemplate restTemplate(){ return new RestTemplate(); } } 참고 사이트Circular Dependency in Spring Boot" }, { "title": "OSError: [Errono 48] Address already in use", "url": "/posts/OSError-Errono-48-Address-already-in-use/", "categories": "Error", "tags": "flask", "date": "2022-04-07 05:43:00 +0900", "snippet": "Error Flask를 실행했더니 다음과 같이 이미 사용되고 있다고 에러가 발생하였다. Error 해결 다음 명령어로 핸재 돌아가고 있는 프로세스를 확인한다. ps -ef | grep python 프로세스의 pid를 확인하고 프로세스를 죽인다. kill -9 [pid] " }, { "title": "transformers Installation Error - Failed building wheel for tokenizers", "url": "/posts/transformers-Installation-Error-Failed-building-wheel-for-tokenizers/", "categories": "Error", "tags": "kobert, transformers", "date": "2022-04-06 07:32:00 +0900", "snippet": "Error Kobert를 다운 받는 중 다음과 같은 에러가 발생했다. ERROR: Failed building wheel for tokenizers Failed to build tokenizers ERROR: Could not build wheels for tokenizers which use PEP 517 and cannot be installed directly Error 해결 link로 들어가 명령어를 copy 한 후 terminal에 입력해줬다. - `curl --proto &#39;=https&#39; --tlsv1.2 -sSf https://sh.rustup.rs | sh` 터미널을 재시작 하고 pip install transformers==2.5.1 후 Kobert를 재설치 했더니 error가 해결 되었다. 참고 사이트[Solved] transformers Installation Error - Failed building wheel for tokenizers" }, { "title": "ERROR: Could not install packages due to an OSError: [Errno 2] No such file or directory: &#39;/Users/lyk/opt/anaconda3/envs/env01/lib/python3.6/site-packages/numpy-1.19.5.dist-info/METADATA’", "url": "/posts/ERROR-Could-not-install-packages-due-to-an-OSError-Errno-2-No-such-file-or-directory-'-Users-lyk-opt-anaconda3-envs-env01-lib-python3.6-site-packages-numpy-1.19.5.dist-info-METADATA/", "categories": "Error", "tags": "conda, pip", "date": "2022-04-06 06:57:00 +0900", "snippet": "Error pip install 뭐시기만 하면 다음과 같은 에러가 발생했다. Error 해결 잘 읽어보면 METADATA가 없다고 한다. 직접 들어가보니 정말 METADATA가 없었다. numpy-1.19.5.dist-info에 METADATA가 없어 numpy-1.19.2.dist-info에 있는 METADATA를 복사해왔더니 해결 되었다." }, { "title": "Swagger Whitelabel Error Page", "url": "/posts/Swagger-Whitelabel-Error-Page/", "categories": "Error", "tags": "swagger, whitelabel", "date": "2022-04-05 08:02:00 +0900", "snippet": "Error swagger dependency를 다음과 같이 설정했다. &amp;lt;dependency&amp;gt; &amp;lt;groupId&amp;gt;io.springfox&amp;lt;/groupId&amp;gt; &amp;lt;artifactId&amp;gt;springfox-swagger2&amp;lt;/artifactId&amp;gt; &amp;lt;version&amp;gt;3.0.0&amp;lt;/version&amp;gt; &amp;lt;/dependency&amp;gt; &amp;lt;dependency&amp;gt; &amp;lt;groupId&amp;gt;io.springfox&amp;lt;/groupId&amp;gt; &amp;lt;artifactId&amp;gt;springfox-swagger-ui&amp;lt;/artifactId&amp;gt; &amp;lt;version&amp;gt;3.0.0&amp;lt;/version&amp;gt; &amp;lt;/dependency&amp;gt; &amp;lt;dependency&amp;gt; &amp;lt;groupId&amp;gt;io.springfox&amp;lt;/groupId&amp;gt; &amp;lt;artifactId&amp;gt;springfox-boot-starter&amp;lt;/artifactId&amp;gt; &amp;lt;version&amp;gt;3.0.0&amp;lt;/version&amp;gt; &amp;lt;/dependency&amp;gt; swagger 설정을 제대로 했음에도 불구하고 다음과 같이 whitelabel page가 떴다. Error 해결 2.x 버전인 경우 http://localhost:8080/swagger-ui.html 3.x 버전인 경우 http://localhost:8080/swagger-ui/index.html 로 들어가야 한다." }, { "title": "Failed to start bean &#39;documentationPluginsBootstrapper&#39;; nested exception is java.lang.NullPointerException", "url": "/posts/Failed-to-start-bean-'documentationPluginsBootstrapper';-nested-exception-is-java.lang.NullPointerException/", "categories": "Error", "tags": "spring boot, swagger", "date": "2022-04-05 07:45:00 +0900", "snippet": "Error swagger를 적용하기 위해 maven dependency에 다음과 같이 추가하였다. &amp;lt;dependency&amp;gt; &amp;lt;groupId&amp;gt;io.springfox&amp;lt;/groupId&amp;gt; &amp;lt;artifactId&amp;gt;springfox-swagger2&amp;lt;/artifactId&amp;gt; &amp;lt;version&amp;gt;3.0.0&amp;lt;/version&amp;gt; &amp;lt;/dependency&amp;gt; &amp;lt;dependency&amp;gt; &amp;lt;groupId&amp;gt;io.springfox&amp;lt;/groupId&amp;gt; &amp;lt;artifactId&amp;gt;springfox-swagger-ui&amp;lt;/artifactId&amp;gt; &amp;lt;version&amp;gt;3.0.0&amp;lt;/version&amp;gt; &amp;lt;/dependency&amp;gt; &amp;lt;dependency&amp;gt; &amp;lt;groupId&amp;gt;io.springfox&amp;lt;/groupId&amp;gt; &amp;lt;artifactId&amp;gt;springfox-boot-starter&amp;lt;/artifactId&amp;gt; &amp;lt;version&amp;gt;3.0.0&amp;lt;/version&amp;gt; &amp;lt;/dependency&amp;gt; swagger config는 다음과 같이 작성하였다. package kr.pe.playdata.config; import org.springframework.context.annotation.Bean; import org.springframework.context.annotation.Configuration; import springfox.documentation.annotations.ApiIgnore; import springfox.documentation.builders.ApiInfoBuilder; import springfox.documentation.builders.RequestHandlerSelectors; import springfox.documentation.service.ApiInfo; import springfox.documentation.spi.DocumentationType; import springfox.documentation.spring.web.plugins.Docket; import springfox.documentation.swagger2.annotations.EnableSwagger2; @Configuration public class SwaggerConfig { @Bean public Docket swaggerApi(){ return new Docket(DocumentationType.SWAGGER_2).ignoredParameterTypes(ApiIgnore.class) .apiInfo(swaggerInfo()).select() .apis(RequestHandlerSelectors.basePackage(&quot;kr.pe.playdata.controller&quot;)) .build() .useDefaultResponseMessages(false); } private ApiInfo swaggerInfo() { return new ApiInfoBuilder().title(&quot;API Documentation&quot;) .description(&quot;제주들려섬 API 문서 &quot;) .license(&quot;license : 제주들렸섬&quot;).licenseUrl(&quot;http://playdata.io/&quot;).build(); } } 빌드를 하니 다음과 같은 에러가 나왔다. Error 해결 Spring boot 2.6버전 이후에 spring.mvc.pathmatch.matching-strategy 값이 ant_apth_matcher에서 path_pattern_parser로 변경되면서 몇몇 라이브러리(swagger포함)에 오류가 발생한다고 한다. application.properties에 다음과 같이 추가를 한다. spring.mvc.pathmatch.matching-strategy = ANT_PATH_MATCHER application.yml이라면 다음과 같이 추가해준다. spring: mvc: pathmatch: matching-strategy: ant_path_matcher spring-boot-starter-parent의 버전을 2.5.x 버전으로 낮추는 방법도 있다.참고 사이트 [swagger 연동을 할려고 하는데 에러가 발생합니다 - 인프런 질문 &amp;amp; 답변](https://www.inflearn.com/questions/230160) " }, { "title": "Index build failed :: caused by :: Can’t extract geo keys", "url": "/posts/Index-build-failed-caused-by-Can-t-extract-geo-keys/", "categories": "Error", "tags": "2dsphere, createIndex, spring data mongodb", "date": "2022-04-03 02:12:00 +0900", "snippet": "Error mongoDB의 GeoJSON을 사용하기 위해 다음과 같이 mongoDB에 쿼리를 날렸더니 에러가 떴다. db.visitJeju.createIndex({location:&quot;2dsphere&quot;}) Error Error 해결 무엇때문인지 ObjectId(’624708b37881cf12acabc8cc’) 요놈의 index를 못 만드는거 같아 조회를 해봤더니 다음과 같았다. coordinates를 살펴보니 숫자가 들어가 있지 않고 string으로 들어가 있어 에러가 난 것이다. 바로 숫자로 고쳐 다시 돌려보니 Error가 해결 되었다. " }, { "title": "unable to find index for $geoNear query", "url": "/posts/unable-to-find-index-for-$geoNear-query/", "categories": "Error", "tags": "mongodb, near, spring data mongodb", "date": "2022-04-01 12:26:00 +0900", "snippet": "Error mongoDB 데이터 { &quot;_id&quot; : ObjectId(&quot;6245f6edf2aa51bc5bae594c&quot;), &quot;name&quot; : &quot;제주커피박물관 Baum&quot;, &quot;location&quot; : { &quot;type&quot; : &quot;Point&quot;, &quot;coordinates&quot; : [ 126.8990639, 33.4397954 ] } } { &quot;_id&quot; : ObjectId(&quot;6245f6eef2aa51bc5bae594d&quot;), &quot;name&quot; : &quot;신산리 마을카페&quot;, &quot;location&quot; : { &quot;type&quot; : &quot;Point&quot;, &quot;coordinates&quot; : [ 126.8759347, 33.3765812 ] } } coordinates는 경도, 위도 순이다. VO VisitJejuLocation package kr.pe.playdata.domain; import lombok.Data; import org.springframework.data.annotation.Id; import org.springframework.data.mongodb.core.mapping.Document; @Data @Document(collection=&quot;places&quot;) public class VisitJejuLocation { @Id private String id; private String name; private Location location; } Location package kr.pe.playdata.domain; import lombok.Data; import org.springframework.data.geo.Point; import org.springframework.data.mongodb.core.mapping.Document; import java.util.List; @Data @Document public class Location { private String type; private List&amp;lt;String&amp;gt; coordinates; } 컨트롤러 package kr.pe.playdata.controller; import kr.pe.playdata.domain.VisitJejuLocation; import kr.pe.playdata.service.LocationService; import org.springframework.beans.factory.annotation.Autowired; import org.springframework.data.geo.Distance; import org.springframework.data.geo.Metrics; import org.springframework.data.geo.Point; import org.springframework.web.bind.annotation.GetMapping; import org.springframework.web.bind.annotation.RequestMapping; import org.springframework.web.bind.annotation.RequestParam; import org.springframework.web.bind.annotation.RestController; import java.util.List; @RestController @RequestMapping(&quot;/map&quot;) public class MapController { @Autowired private LocationService locationService; @GetMapping(&quot;/findNear&quot;) public List&amp;lt;VisitJejuLocation&amp;gt; findNear( @RequestParam String longtitude, @RequestParam String latitude, @RequestParam double distance ){ Point p = new Point(Double.valueOf(longtitude), Double.valueOf(latitude)); Distance d = new Distance(distance, Metrics.KILOMETERS); List&amp;lt;VisitJejuLocation&amp;gt; li = locationService.findNear(p,d); return li; } } Service Interface package kr.pe.playdata.service; import kr.pe.playdata.domain.VisitJejuLocation; import org.springframework.data.geo.Distance; import org.springframework.data.geo.Point; import java.util.List; public interface LocationService { public List&amp;lt;VisitJejuLocation&amp;gt; findNear(Point p, Distance d); } Implements package kr.pe.playdata.service.impl; import kr.pe.playdata.domain.VisitJejuLocation; import kr.pe.playdata.repository.LocationMongoRepo; import kr.pe.playdata.service.LocationService; import org.springframework.beans.factory.annotation.Autowired; import org.springframework.data.geo.Distance; import org.springframework.data.geo.Point; import org.springframework.stereotype.Service; import java.util.List; @Service public class LocationServiceImpl implements LocationService { @Autowired private LocationMongoRepo locationMongoRepo; public List&amp;lt;VisitJejuLocation&amp;gt; findNear(Point p, Distance d){ return locationMongoRepo.findByLocationNear(p, d); } } Repository package kr.pe.playdata.repository; import kr.pe.playdata.domain.VisitJejuLocation; import org.springframework.data.geo.Distance; import org.springframework.data.geo.Point; import org.springframework.data.mongodb.repository.MongoRepository; import org.springframework.data.mongodb.repository.Query; import org.springframework.stereotype.Repository; import java.util.List; @Repository public interface LocationMongoRepo extends MongoRepository&amp;lt;VisitJejuLocation, String&amp;gt; { List&amp;lt;VisitJejuLocation&amp;gt; findByLocationNear(Point p, Distance d); } 위와 같이 코드를 작성 후 postman으로 다음과 같이 보냈다. localhost:8080/map/findNear?latitude=33.43&amp;amp;longtitude=126.89&amp;amp;distance=7 결과는 다음과 같이 에러가 발생하였다. planner returned error :: caused by :: unable to find index for $geoNear query&#39; on server xx.xxx.xxx.xxx:27017; nested exception is com.mongodb.MongoQueryException: Query failed with error code 291 and error message &#39;error processing query: ns=jeju.placesTree: GEONEAR field=location maxdist=0.0010975 isNearSphere=1 Error 해결 mongoDB에 특정 field에 2dsphere index를 생성해줘야 한다. db.places.createIndex( { location: &quot;2dsphere&quot; } ) 참고 사이트Spring Data MongoDB - Aggregation Operation - 02$geoNear (aggregation)예제로 배워보는 상황 별 MongoDB 위치 기반 쿼리[MongoDB] MongoDB와 GeoJSON을 이용하여 근접 위치 확인하기" }, { "title": "The kernel appears to have died. It will restart automatically by using XGBoost", "url": "/posts/The-kernel-appears-to-have-died.-It-will-restart-automatically-by-using-XGBoost/", "categories": "Error", "tags": "XGBoost, jupyter notebook", "date": "2022-03-25 19:10:00 +0900", "snippet": "Error Jupyter notebook에서 XGBoost를 사용하기 위해 python -m pip install xgboost를 하였고 사용하려고 하니 다음과 같은 에러가 났다. The kernel appears to have died. It will restart automatically by using Error 해결 OS 차이로 인한 에러인것 같다. conda install -c anaconda py-xgboost 로 설치하니 잘 돌아갔다." }, { "title": "MongoDB 랜섬웨어 감염", "url": "/posts/MongoDB-%EB%9E%9C%EC%84%AC%EC%9B%A8%EC%96%B4-%EA%B0%90%EC%97%BC/", "categories": "Error", "tags": "mongodb, 랜섬웨어", "date": "2022-03-24 01:25:00 +0900", "snippet": "Error aws EC2에 mongoDB를 설치하였고 어느날 들어가니 데이터가 다 날아가고 이상한 말들이 적혀 있었다. 0.026 비트코인을 지불하면 잃어버린 데이터를 복구해주겠다는 것이고 무시할 경우 GDPR에 신고하여 법적인 책임을 물게 하겠다는 것이다. 다행히도 DB에는 공공데이터밖에 없었다. Error 해결 계정 인증이 되어있지 않아 쉽게 해킹이 되었던 것이다. 로컬의 경우 네트워크 망이 내부망으로 구성이 되어 있어 상관이 없었지만 네트워크 망이 public이 되면 계정 설정을 따로 하지 않으면 외부에서 아무나 mongoDB에 admin 권한으로 접근할 수 있게 된다." }, { "title": "TypeError: &#39;int&#39; object is not callable", "url": "/posts/TypeError-'int'-object-is-not-callable/", "categories": "Error", "tags": "len, python3", "date": "2022-03-22 03:35:00 +0900", "snippet": "Error python으로 알고리즘 문제를 풀던 중 len()함수가 도저히 먹히지가 않고 다음과 같은 에러가 계속 나왔다. Traceback (most recent call last): File &quot;/Users/lyk/Documents/CPP/t.py&quot;, line 49, in &amp;lt;module&amp;gt; if(check(mid,l,k)): File &quot;/Users/lyk/Documents/CPP/t.py&quot;, line 14, in check print(len(temp_l)) TypeError: &#39;int&#39; object is not callable Error 해결 len이라는 변수를 사용해서 생긴 에러였다. 이미 정해져 있는 함수 이름은 변수 이름으로 사용하지 말자." }, { "title": "sh: react-scripts: command not found", "url": "/posts/sh-react-scripts-command-not-found/", "categories": "Error", "tags": "npm, react", "date": "2022-03-17 03:45:00 +0900", "snippet": "Error github에서 react가 있는 폴더를 pull을 하여 npm start 명령어를 실행하였지만 script가 없어 실행이 불가능하다고 다음과 같은 에러가 나왔다. &amp;gt; test@0.1.0 start &amp;gt; react-scripts start sh: react-scripts: command not found Error 해결 다음 명령어를 실행하여 node_modules를 만들어줌 npm add react-scripts or npm install -save react-scripts 참고 사이트[오류] /bin/sh: react-scripts: command not found" }, { "title": "No module named &#39;pandas_profiling’", "url": "/posts/No-module-named-'pandas_profiling/", "categories": "Error", "tags": "pandas, pandas_profiling", "date": "2022-03-17 03:09:00 +0900", "snippet": "Error env01이라는 내가 만든 conda 가상환경에서 pip install pandas-profiling 명령어로 pandas-profiling으로 설치 후 jupyter notebook에서 pandas_profiling 을 import 하였지만 다음과 같은 에러가 발생하였다. Error 해결 env01은 python 3.6 버전이었다. 아무리 삭제하고 재설치를 해도 되지 않아 깔끔하게 새로운 가상환경을 만들어 진행해보았다. conda create -n env03 새로운 가상환경은 python 버전이 3.9로 설치가 되었고 여기에 pandas-profiling을 설치해보았다. pip install pandas-profiling 이후 jupyter notebook으로 들어가 import를 하였더니 성공적으로 잘 되었다. " }, { "title": "Object of type &#39;Decimal&#39; is not JSON serializable", "url": "/posts/Object-of-type-'Decimal'-is-not-JSON-serializable/", "categories": "Error", "tags": "json, python3", "date": "2022-03-12 08:53:00 +0900", "snippet": "Error 다음과 같이 flask에서 mysql db와 연동하여 값을 얻어와 json 형태로 바꿨을 때 error가 발생한다. def empall(self): all = [] try: conn = getConnection() cursor = conn.cursor() try: cursor.execute(&quot;select * from emp01&quot;) rows = cursor.fetchall() objects_list = [] for row in rows: d = collections.OrderedDict() d[&#39;empno&#39;] = row[0] d[&#39;ename&#39;] = row[1] d[&#39;sal&#39;] = row[2] objects_list.append(d) all = json.dumps(objects_list) except Exception as e: print(e) except Exception as e: print(e) finally: cursor.close() conn.close() return all Error Object of type &#39;Decimal&#39; is not JSON serializable Error 해결 oracle db는 소수를 json 형태로 잘 바꿔주지만 mysql은 잘 바꿔주지 못하는것 같다. 소수가 나올 수 있는 row[2] 부분을 int(row[2]) 혹은 float(row[2])로 바꾸어 해결하였다." }, { "title": "PermissionError: [Errno 13] Permission denied", "url": "/posts/PermissionError-Errno-13-Permission-denied/", "categories": "Error", "tags": "flask, permission error", "date": "2022-03-11 20:02:00 +0900", "snippet": "Error mac에서 vscode로 flask app.py를 돌릴려고 하니 다음과 같은 에러가 발생하였다. Error 해결 다음 명령어로 app.py를 실행시킨다. sudo python app.py " }, { "title": "NameError: name &#39;Tagger&#39; is not defined", "url": "/posts/NameError-name-'Tagger'-is-not-defined/", "categories": "Error", "tags": "colab, mecab, tagger", "date": "2022-03-09 21:18:00 +0900", "snippet": "Error 구글 colab에서 mecab을 설치 후 다음과 같은 명령어를 실행했더니 에러가 발생하였다. # mecab 설치 !git clone https://github.com/SOMJANG/Mecab-ko-for-Google-Colab.git %cd Mecab-ko-for-Google-Colab !bash install_mecab-ko_on_colab190912.sh # mecab 실행 from konlpy.tag import Mecab m = Mecab() 에러 NameError Traceback (most recent call last) /usr/local/lib/python3.6/dist-packages/konlpy/tag/_mecab.py in __init__(self, dicpath) 107 try: --&amp;gt; 108 self.tagger = Tagger(&#39;-d %s&#39; % dicpath) 109 self.tagset = utils.read_json(&#39;%s/data/tagset/mecab.json&#39; % utils.installpath) NameError: name &#39;Tagger&#39; is not defined During handling of the above exception, another exception occurred: Exception Traceback (most recent call last) Error 해결 mecab을 다음 링크를 통해 다운 받는다. # konlpy, Mecab 형태소 분석기 설치 스크립트 실행 !curl -s https://raw.githubusercontent.com/teddylee777/machine-learning/master/99-Misc/01-Colab/mecab-colab.sh | bash 참고 사이트구글 코랩(Google Colab)에서 Mecab 형태소 분석기, konlpy 쉽게 설치하기" }, { "title": "UsageError: Line magic function %%writefile not found.", "url": "/posts/UsageError-Line-magic-function-writefile-not-found/", "categories": "Error", "tags": "magic function, python3, writefile", "date": "2022-03-07 08:49:00 +0900", "snippet": "Error# jupyter notebook 상에서 파일 생성 명령어, 이미 있다면 덮어씌운다.%%writefile fibo.pydef fib(n): a, b = 0, 1 while b&amp;lt;n: # 조건이 true인 경우에만 실행되는 반복문 print(b, end=&#39; &#39;) a, b = b, a+b 위와 같은 코드를 작성하였더니 다음과 같은 에러가 발생하였다. Error 해결 magic command %%writefile은 jupyter notebook cell의 첫번째 줄에 작성해야 한다. 다음과 같이 수정하였더니 정상적으로 동작했다. %%writefile fibo.py # jupyter notebook 상에서 파일 생성 명령어, 이미 있다면 덮어씌운다. def fib(n): a, b = 0, 1 while b&amp;lt;n: # 조건이 true인 경우에만 실행되는 반복문 print(b, end=&#39; &#39;) a, b = b, a+b 참고 사이트python jupyter magic %%writefile returns SyntaxError: invalid syntax" }, { "title": "unable to open swap file “Filename” for recovery impossible", "url": "/posts/unable-to-open-swap-file-Filename-for-recovery-impossible/", "categories": "Error", "tags": "vi, vim, swap file", "date": "2022-02-27 03:57:00 +0900", "snippet": "Error python 파일을 고치기 위해 vim으로 열었지만 이전과는 다르게 다음과 같이 에러가 나면서 이상해졌다. Error 해결 메모리 공간이 부족하거나 알 수 없는 이유로 인해서 편집 이력이 있었던 파일의 스왑(SWAP) 파일을 열지 못하여 발생하는 문제이다. 아니나 다를까 df -h 명령으로 메모리를 확인을 해보니 디스크 용량이 100%가 차 있는것을 볼 수 있었다. 파일을 지우거나 디스크 용량을 늘려주어 해결하였다." }, { "title": "Attempting to deserialize object on a CUDA device but torch.cuda.is_available() is False. If you are running on a CPU-only machine, please use torch.load with map_location=torch.device(&#39;cpu&#39;) to map your storages to the CPU.", "url": "/posts/Attempting-to-deserialize-object-on-a-CUDA-device-but-torch.cuda.is_available()-is-False.-If-you-are-running-on-a-CPU-only-machine,-please-use-torch.load-with-map_location=torch.device('cpu')-to-map-your-storages-to-the-CPU/", "categories": "Error", "tags": "cpu, deep learning, gpu, kobert, machine learning, nlp", "date": "2022-02-22 18:31:00 +0900", "snippet": "Error GPU로 학습하여 저장한 모델 전체를 cpu로 불러오니 에러가 발생하였다. Error 해결 코드를 다음과 같이 변경하여 불러오니 해결되었다. //변경 전 model1 = torch.load(&#39;./7emotions_model.pt&#39;) //변경 후 model1 = torch.load(&#39;./7emotions_model.pt&#39;,map_location=&#39;cpu&#39;) 참고 사이트모델 저장하기 &amp;amp; 불러오기 - PyTorch Tutorials 1.10.2+cu102 documentation" }, { "title": "python3: can&#39;t open file &#39;python3&#39;: [Errno 2] No such file or directory", "url": "/posts/python3-can't-open-file-'python3'/", "categories": "Error", "tags": "jupyter notebook, pyspark, python3", "date": "2022-02-22 06:10:00 +0900", "snippet": "Error pyspark를 jupyter notebook으로 사용을 하기 위해 환경변수 설정을 해주었고 다시 되돌리기 위해 환경변수를 제거 했지만 그대로 jupyter notebook으로 돌아감 결국 고치려다 다음과 같이 환경변수를 설정해줬지만 에러가 발생 #export PYSPARK_DRIVER_PYTHON=jupyter #export PYSPARK_DRIVER_PYTHON_OPTS=notebook export PYSPARK_DRIVER_PYTHON=python3 export PYSPARK_DRIVER_PYTHON_OPTS=python3 Error 해결 .bashrc에서 두 줄을 주석처리 하였지만 env 명령어로 환경변수를 확인했을 때 그대로 남아 있었다. #export PYSPARK_DRIVER_PYTHON=jupyter #export PYSPARK_DRIVER_PYTHON_OPTS=notebook 계정을 나갔다 들어오거나 재부팅을 하면 환경변수가 사라진 것을 볼 수 있다. 위에서 난 에러는 쓸데 없이 python3를 붙여줘서 난 에러이다." }, { "title": "FileZilla 500 OOPS: chroot", "url": "/posts/FileZilla-500-OOPS-chroot/", "categories": "Error", "tags": "filezilla", "date": "2022-02-22 03:32:00 +0900", "snippet": "Error vsftpd를 설치 후 FileZilla로 연결 요청을 보냈지만 다음과 같은 에러가 발생 Error 해결 SELinux의 방화벽을 닫아준다. setenforce 0 SELinux를 임시로 비활성화 시킨다. getenforce 를 하면 permissive 상태로 되어 있는 것을 볼 수 있다. SELinux 완전히 끄기 권장 하지 않는 방법이지만 /etc/sysconfig/selinux 로 들어가 SELINUX를 disabled로 바꿔준다. vim /etc/sysconfig/selinux 위 그림과 같이 SELINUX를 disabled로 바꿔준다. 참고 사이트Linux SELinux 끄기 및 임시 비활성화 방법 - JooTC" }, { "title": "Execution failed for task &#39;:MemberApp.main()&#39;.", "url": "/posts/Execution-failed-for-task-'MemberApp.main()'/", "categories": "Error", "tags": "Spring, intellij", "date": "2022-02-15 18:01:00 +0900", "snippet": "에러 발생 다음과 같은 에러가 발생하였다. Execution failed for task &#39;:MemberApp.main()&#39;. 에러 해결 설정에 들어가 build를 gradle에서 IntelliJ IDEA로 둘 다 바꿔줬다. " }, { "title": "로컬에서 가상환경의 IP로 접근이 불가능합니다.", "url": "/posts/%EB%A1%9C%EC%BB%AC%EC%97%90%EC%84%9C-%EA%B0%80%EC%83%81%ED%99%98%EA%B2%BD%EC%9D%98-IP%EB%A1%9C-%EC%A0%91%EA%B7%BC%EC%9D%B4-%EB%B6%88%EA%B0%80%EB%8A%A5%ED%95%A9%EB%8B%88%EB%8B%A4/", "categories": "Error", "tags": "CentOS, IP, 방화벽", "date": "2022-02-08 19:04:00 +0900", "snippet": "에러 발생 가상환경의 ip 주소는 192.168.56.100이고 port 번호 9870을 통해 hadoop에 들어가려고 했으나 다음과 같이 실패 해결 방법 가상환경의 방화벽을 내리니 해결할 수 있었다. 방화벽 내리는 방법 systemctl stop firewalld systemctl disable firewalld 방화벽 다시 올리는 방법 systemctl start firewalld systemctl enable firewalld 참고 사이트RHEL/CentOS 에서 방화벽(firewall) 설정하기[CentOS 7] 방화벽 해제하기 - firewall-cmd" }, { "title": "Datanode가 브라우저에 하나밖에 안 나옵니다.", "url": "/posts/Datanode%EA%B0%80-%EB%B8%8C%EB%9D%BC%EC%9A%B0%EC%A0%80%EC%97%90-%ED%95%98%EB%82%98%EB%B0%96%EC%97%90-%EC%95%88-%EB%82%98%EC%98%B5%EB%8B%88%EB%8B%A4/", "categories": "Error", "tags": "datanodes, hadoop", "date": "2022-02-02 03:25:00 +0900", "snippet": "에러 발생 hadoop을 실행했고 정상적으로 잘 작동하는거 같으나 브라우저로 접속하여 datanodes를 확인해보면 datanode가 하나밖에 보이지 않는다.문제 해결 /etc/hosts에 들어가 ip 등록이 잘 되어 있는지 확인한다. vi /etc/hosts 위와 같이 hadoop00에 대해서 ip가 중복적으로 들어가 있으면 안 된다. 127.0.0.1 hadoop00을 삭제하고 저장하면 에러가 해결된다." }, { "title": "백준 python RecursionError", "url": "/posts/%EB%B0%B1%EC%A4%80-python-RecursionError/", "categories": "Error", "tags": "RecursionError, python3, 백준", "date": "2022-02-02 03:10:00 +0900", "snippet": "Error 백준 문제를 풀던 도중 recursion error가 발생하였다. Error 해결 백준의 경우 python 재귀함수의 호출 스택이 1000까지로 설정되어 있다. 다음을 코드에 추가 시켜 함수 스택 limit을 조절할 수 있다. import sys sys.setrecursionlimit(10**6) 참고 사이트런타임 에러 (RecursionError)" }, { "title": "Permission denied (publickey,gssapi-keyex,gssapi-with-mic)", "url": "/posts/Permission-denied-(publickey,gssapi-keyex,gssapi-with-mic)/", "categories": "Error", "tags": "hadoop, ssh", "date": "2022-02-02 03:10:00 +0900", "snippet": "에러 발생 원격 접속을 하려고 하니 다음과 같은 에러가 발생했다. 에러 해결 에러를 해결하기 위해 여러가지 의심을 해봐야한다. A→B로 원격 접속을 한다면 B의 /etc/ssh/sshd_config 파일에서 PasswordAuthentication을 yes로 바꿔주어야 한다. 다음 명령어를 통해 sshd_config 파일을 편집해준다. vi /etc/ssh/sshd_config 변경을 완료하였으면 다음 명령어로 sshd를 재시작해줘야한다. systemctl restart sshd B계정에서의 .ssh 파일의 권한을 700으로 바꿔준다. chmod 700 .ssh 만약 위와 같은 상황을 모두 했는데도 hadoop을 실행할 때 에러가 난다면 master의 workers에 slave를 제대로 추가했는지 확인해보자 vi hadoop-3.2.2/etc/hadoop/workers " }, { "title": "Error: Failed to download metadata for repo &#39;appstream&#39;: Cannot prepare internal mirrorlist: No URLs in mirrorlist", "url": "/posts/Error-Failed-to-download-metadata-for-repo-'appstream'/", "categories": "Error", "tags": "CentOS8", "date": "2022-02-01 18:41:00 +0900", "snippet": "Error CentOS8에서 wget을 설치하기 위해 dnf install을 사용했더니 다음과 같은 에러가 났다. CentOS8의 서비스가 22년부터 서비스가 중단되고 CentOS Stream으로 전환된다. 해결 방법 CentOS7을 사용하자. 기존에 Mirror site를 Vault로 전환하여 dnf를 사용한다. sed -i &#39;s/mirrorlist/#mirrorlist/g&#39; /etc/yum.repos.d/CentOS-Linux-* sed -i &#39;s|#baseurl=http://mirror.centos.org|baseurl=http://vault.centos.org|g&#39; /etc/yum.repos.d/CentOS-Linux-* 당장은 해결이 가능하지만 해당 Reop는 더 이상 Package의 유지보수가 없으므로 보안에 취약하다. 근본적인 해결을 위해서는 다른 배포판(ex. rocky linux 등)이나 CentOS 8 Stream, REHL 8로 전환해야 한다. CentOS 8 Stream 전환 방법Update CentOS 8 to CentOS Stream [in 3 Easy Steps]" }, { "title": "Error: (conn=335) Table &#39;CTLGS&#39; already exists (state=42S01,code=1050)", "url": "/posts/Table-'CTLGS'-already-exists/", "categories": "Error", "tags": "MySQL, hadoop, hive", "date": "2022-02-01 04:27:00 +0900", "snippet": "에러 발생 mysql에 hive 스키마를 생성하려고 schematool -initSchema -dbType mysql 명령어를 사용하니 다음과 같은 에러가 나왔다. 에러 해결 위 에러는 database의 이름이 중복되었기 때문에 발생한 에러이다. 다음과 같이 해결하였다. mysql -u root -p drop database hive; " }, { "title": "Exception in thread &quot;main&quot; java.lang.NoSuchMethodError: com.google.common.base.Preconditions.checkArgument (ZLjava/lang/String;Ljava/lang/Object;)", "url": "/posts/NoSuchMethodError/", "categories": "Error", "tags": "guava, hadoop, hive", "date": "2022-02-01 04:12:00 +0900", "snippet": "에러 발생 hive를 실행시켰더니 다음과 같은 에러가 발생하였다. 에러 해결 guava-19.0.jar를 guava-27.0-jre.jar로 바꾸었더니 해결되었다. rm /home/hadoop/hive-3.1.2/lib/guava-19.0.jar cp /home/hadoop/hadoop-3.2.2/share/hadoop/hdfs/lib/guava-27.0-jre.jar /home/hadoop/flume-1.9.0/lib/ 참고 사이트java.lang.NoSuchMethodError: com.google.common.base.Preconditions.checkArgument" }, { "title": "com.ctc.wstx.exc.WstxParsingException: Illegal character entity: expansion character (code 0x8 at [row,col,system-id]:[3215,96,&quot;file:/home/hadoop/hive-3.1.2/conf/hive-site.xml&quot;]", "url": "/posts/Illegal-character-entity/", "categories": "Error", "tags": "hive, hadoop, hive-site.xml", "date": "2022-02-01 04:12:00 +0900", "snippet": "Error 발생 hive를 실행하였더니 다음과 같은 에러가 발생하였다. Error 해결 에러에서 나온대로 hive-site.xml의 3215번째 줄을 보았더니 다음과 같이 이상한 문자가 있어 빼주었다. for 뒤에 문제가 되는 4개의 문자를 빼주었다. 빼주고 다시 hive를 실행했더니 해결이 되었다. " }, { "title": "ssh: connect to host hadoop port 22: No route to host", "url": "/posts/connect-to-host-hadoop-port-22/", "categories": "Error", "tags": "ssh, linux", "date": "2022-01-26 09:35:00 +0900", "snippet": "에러 발생 ssh: connect to host hadoop port 22: No route to host 라는 에러 문구가 뜬다.문제 해결 우선 hostname -I 명령어를 통해 내 ip 주소를 확인한다. 확인해본 결과 ip가 내가 원하는 ip로 고정되어 있지 않았다. ip를 고정하기 위해 /etc/sysconfig/network-scripts/ifcfg-eth0 을 다음과 같이 변경하였다. DEVICE=eth0 HWADDR=08:00:27:21:95:5B TYPE=Ethernet ONBOOT=yes BOOTPROTO=static IPADDR=192.168.56.103 NETMASK=255.255.255.0 GATEWAY=192.168.56.1 NETWORK=192.168.56.0 알아보니 가상머신 설정에 있는 MAC address를 잘못 입력하여 일치하지 않아 에러가 났던 것이다. " }, { "title": "IT IS POSSIBLE THAT SOMEONE IS DOING SOMETHING NASTY!", "url": "/posts/IT-IS-POSSIBLE-THAT-SOMEONE-IS-DOING-SOMETHING-NASTY!/", "categories": "Error", "tags": "ssh, linux", "date": "2022-01-26 09:31:00 +0900", "snippet": "에러 발생 ssh 원격 접속을 하려 했는데 다음과 같은 에러가 발생했다. 문제 해결 문제는 접속 시 man-in-the-middle attack이라고 판단하여 보안상 문제가 발생할 수 있어 막는거 같다. 다음과 같은 명령어를 실행하면 문제 없이 원격접속이 가능하다. rm -rf ~/.ssh/known_hosts " }, { "title": "datanodes가 보이지 않음", "url": "/posts/datanodes%EA%B0%80-%EB%B3%B4%EC%9D%B4%EC%A7%80-%EC%95%8A%EC%9D%8C/", "categories": "Error", "tags": "datanodes, hadoop, jps", "date": "2022-01-22 21:39:00 +0900", "snippet": "에러 발생 하둡 실행 후 jps 명령어를 통해 실행중인 Java Virtual Machine에 올라간 프로세스를 볼 수 있는데 datanodes가 올라와 있지 않는다.문제 해결 기존 데이터 폴더를 모두 삭제하고 다시 만든 후 dhfs namenode -format 을 하고 ./start-all.sh 로 실행하면 datanodes가 다시 뜰 것이다." }, { "title": "You do not have permission to open the application", "url": "/posts/You-do-not-have-permission-to-open-the-application/", "categories": "Error", "tags": "Big sur, DBeaver", "date": "2021-12-24 06:12:00 +0900", "snippet": "💡 어제까지 사용했던 DBeaver가 다음 날 다시 켰더니 열 수 있는 권한이 없다고 한다.Error해결 방법 pkutil --check-signature /Application/앱이름.app 을 터미널에서 실행해보자 invalid 상태라고 뜬다. codesign --force --deep --sign - /Applications/앱이름.app 을 터미널에 실행 시켜 해결한다. 완료 되면 앱을 실행 시킬 수 있게 된다 원인 모든 앱은 오용되거나 변조되지 않았는지 확인하기 위해 Apple의 서명을 받는다. 수정 과정에서 뭔가 서명이 잘못된거 같다고 생각된다.참고 사이트[macOS] Big sur에서 권한이 없다며 어플리케이션이 안열리는 경우의 해결" }, { "title": "Failed to create the Java Virtual Machine", "url": "/posts/Failed-to-create-the-Java-Virtual-Machine/", "categories": "Error", "tags": "STS, Spring, VM", "date": "2021-12-23 22:02:00 +0900", "snippet": "💡 STS를 실행하였더니 Java VM을 생성할 수 없다고 떴다.해결 방법 응용 프로그램에 들어가 STS 아이콘을 우 클릭 후 패지지 내용 더보기를 눌러 STS.ini를 찾아 다음과 같이 코드를 -vmargs 위에 추가해줍니다. -vm /Library/Java/JavaVirtualMachines/[자바 버전]/Contents/Home/bin/java " }, { "title": "Mac Launchpad 오류", "url": "/posts/Mac-Launchpad-%EC%98%A4%EB%A5%98/", "categories": "Error", "tags": "Mac, launchpad", "date": "2021-12-18 21:40:00 +0900", "snippet": "💡 맥의 런치 패드에 삭제된 아이콘이 있고 새로 다운로드한 아이콘이 없는 상황해결 방법 터미널에 다음과 같이 명령어를 작성한다. defaults write com.apple.dock ResetLaunchPad -bool true; killall Dock " }, { "title": "Loading class &#39;com.mysql.jdbc.Driver&#39;. This is deprecated. The new driver class is &#39;com.mysql.cj.jdbc.Driver&#39;.", "url": "/posts/Loading-class-'com.mysql.jdbc.Driver'.-This-is-deprecated.-The-new-driver-class-is-'com.mysql.cj.jdbc.Driver'/", "categories": "Error", "tags": "Java, JDBC, driver", "date": "2021-12-01 20:49:00 +0900", "snippet": "💡 Loading class &#39;com.mysql.jdbc.Driver&#39;. This is deprecated. The new driver class is &#39;com.mysql.cj.jdbc.Driver&#39;.Deprecated 의미를 찾아봤더니 사용 되지 않는다는 뜻이다.Error 해석 &#39;com.mysql.jdbc.Driver&#39;가 더 이상 쓰이지 않으니 &#39;com.mysql.cj.jdbc.Driver&#39;를 사용하라는 이야기이다.해결 현재 내가 새용하고 있는 JDBC 커넥터 라이브러리는 mysql-connector-java-8.0.27.jar이다. &#39;com.mysql.jdbc.Driver&#39;를 &#39;com.mysql.cj.jdbc.Driver&#39;로 바꾸니 잘 연동이 된다.참고 사이트[JAVA] Loading class ‘com.mysql.jdbc.Driver’. This is deprecated. The new driver class is ‘com.mysql.cj.jdbc.Driver’." }, { "title": "Failed to open file", "url": "/posts/Failed-to-open-file/", "categories": "Error", "tags": "MySQL", "date": "2021-11-25 04:04:00 +0900", "snippet": "💡 외부 파일을 불러오려고 했는데 파일을 찾을 수 없다는 문구가 떴다.Error 외부 파일 employees.sql 을 불러오려고 했지만 찾을 수 없다고 에러가 나왔다. 현재 경로가 잘못되었다고 판단하여 파일의 절대 경로로 실행해보았다. 처음에 잘 되다가 dump 파일을 못 읽어오는 상태가 되었다. 해결방법 MySQL을 처음에 실행하기 전에 디렉토리를 파일들이 있는 곳으로 이동시킨 후 MySQL을 실행했다. cd /Users/lyk/workspace/eclipse-workspace/DB01/employees mysql -u root -p source employees.sql " }, { "title": "자바란 무엇인가?", "url": "/posts/%EC%9E%90%EB%B0%94%EB%9E%80-%EB%AC%B4%EC%97%87%EC%9D%B8%EA%B0%80/", "categories": "Language, Java", "tags": "java, jvm, bytecode", "date": "2021-11-10 01:46:00 +0900", "snippet": "자바란 무엇인가?자바를 공부하기에 앞서 자바를 왜 써야하는지부터 알아야할거 같다. 그럼 자바가 탄생하게 된 배경부터 알아보자.자바의 역사자바는 썬 마이크로시스템즈의 제임스 고슬링과 다른 연구원들이 개발한 객체 지향적 프로그래밍 언어이며 1995년에 처음으로 출시 되었다.그렇다면 이러한 언어를 왜 만들었을까? C와 C++ 언어로 된 프로그램을 실행하기 위해서는 컴퓨터가 이해할 수 있도록 기계어로 변환을 해주어야 하며 이를 컴파일러라고 한다. 하지만 CPU의 종류에 따라 기계어가 다르기 때문에 CPU에 맞는 컴파일러가 필요했다. 즉 같은 프로그램이라도 CPU가 다르면 실행하기 위해 해당 CPU에 맞는 컴파일러가 필요했다.이러한 불편함을 없애고자 고슬링은 코드를 한번 작성하고 어디에서나 실행될 수 있도록 하는 언어를 개발하였고 이것이 Java이다.자바로 개발된 프로그램은 CPU나 운영 체제의 종류에 관계없이 어디서나 실행할 수 있으며, 이 점이 웹 애플리케이션의 특성과 맞아떨어져 폭발적인 인기를 끌게 되었다.철학자바는 5가지의 핵심 목표를 지닌다. 객체 지향 방법론을 사용 같은 프로그램(바이트코드)이 여러 운영 체제에서 실행될 수 있어야 함 컴퓨터 네트워크 접근 기능이 기본으로 탑재되어야 함 원격 코드를 안전하게 실행할 수 있어야 함 다른 객체 지향 언어들의 좋은 부분만 가지고 와서 사용하기 편해야 함컴파일 과정 C/C++ C/C++은 특정 CPU의 기계어 코드를 직접 생성하면 생성된 기계어 코드가 메모리에 적재되어 바로 실행된다. 그렇기 때문에 CPU가 달라지면 컴파일러가 달라져야 한다. Java java로 작성한 .java 파일을 컴파일 하게 되면 .class파일이 생기고 .class는 JVM이 이해할 수 있는 바이트코드로 이루어진다. JVM(자바 가상 머신)이 바이트 코드를 해석하여 실행한다. JVM의 인터프리터와 JIT 컴파일러는 바이트코드를 각 OS가 실행할 수 있는 기계어로 변환시킨다. 프로세서는 기계어에 따라 동작을 수행한다. 사용자가 본인의 실행환경에 맞는 JVM만 설치한다면 같은 프로그램을 돌릴 수 있다. JVM이란? Java Virtual Machine으로CPU와 OS에 종속받지 않고 바이트코드를 실행할 수 있는 가상 컴퓨터 머신이다. JVM은 바이트코드를 OS가 이해할 수 있도록 해석해준다. java 파일만 있으면 어느 환경에서든 JVM 위에서 실행할 수 있기 때문에 Java가 플랫폼 독립적 언어가 될 수 있는 이유이다.바이트 코드란? 바이트코드는 JVM이 이해할 수 있는 저수준 언어이다. 기존의 언어의 컴파일 결과로 생성되는 오브젝트파일(.obj)와 달리 바이트코드(.class)는 모든 플랫폼의 JVM에서 실행이 가능하다. 직접 코드를 짜서 바이트 코드를 확인해보자 다음은 Test라는 class를 만들어 1+2를 출력하는 코드이다. .java 파일을 컴파일 하면 .class 파일이 생기고 .class 파일을 javap -c로 열면 다음과 같이 나온다. 참고 사이트[Java] 자바의 컴파일 과정자바 (프로그래밍 언어) - 위키백과, 우리 모두의 백과사전" }, { "title": "Python의 heapq와 PriorityQueue 차이", "url": "/posts/Python%EC%9D%98-heapq%EC%99%80-PriorityQueue%EC%9D%98-%EC%B0%A8%EC%9D%B4/", "categories": "Language, Python", "tags": "python3, heapq, PriorityQueue", "date": "2021-10-06 21:19:00 +0900", "snippet": "💡 백준 문제를 풀다가 PriorityQueue는 시간초과가 뜨지만 heapq를 사용하면 시간초과가 뜨지 않았다. 왜 그럴까?해결 결론부터 말하자면 PriorityQueue는 스레드 안전 클래스이고 heapq는 스레드 안전을 보장하지 않는다. PriorityQueue는 스레드 안전을 위한 lock을 제공하기 때문에 잠금 오버 헤드가 있어 시간초과가 났던 것이다." }, { "title": "Node.js의 Express란?", "url": "/posts/Node.js%EC%9D%98-Express%EB%9E%80/", "categories": "Node.js", "tags": "node.js, express", "date": "2021-10-05 08:26:00 +0900", "snippet": "Express란? express는 Node.js를 위한 빠르고 개방적인 간결한 웹 프레임워크이다. express는 Node.js를 사용하여 서버를 개발하고자 하는 개발자들을 위하여 서버를 쉽게 구성할 수 있게 만든 프레임워크이다. 쉽게 말하여 HTTP 통신을 하려면 여러가지 할게 많은데 이런걸 간단하게 해주는것이 express 프레임워크이다.참고 자료Express - Node.js web application framework[JAVASCRIPT] express란?" }, { "title": "Node.js address already in use", "url": "/posts/Node.js-address-already-in-use/", "categories": "Error", "tags": "lsof, port error", "date": "2021-09-29 02:45:00 +0900", "snippet": "💡 Port 번호가 이미 사용되고 있으므로 다른 port 번호를 사용하라는 에러가 발생하였다.에러server.jsevents.js:352 throw er; // Unhandled &#39;error&#39; event ^Error: listen EADDRINUSE: address already in use :::8080 at Server.setupListenHandle [as _listen2] (net.js:1320:16) at listenInCluster (net.js:1368:12) at Server.listen (net.js:1454:7) at Function.listen (/Users/lyk/Documents/GitHub/Support/node_modules/express/lib/application.js:618:24) at Object.&amp;lt;anonymous&amp;gt; (/Users/lyk/Documents/GitHub/Support/server.js:13:5) at Module._compile (internal/modules/cjs/loader.js:1085:14) at Object.Module._extensions..js (internal/modules/cjs/loader.js:1114:10) at Module.load (internal/modules/cjs/loader.js:950:32) at Function.Module._load (internal/modules/cjs/loader.js:790:14) at Function.executeUserEntryPoint [as runMain] (internal/modules/run_main.js:76:12)Emitted &#39;error&#39; event on Server instance at: at emitErrorNT (net.js:1347:8) at processTicksAndRejections (internal/process/task_queues.js:82:21) { code: &#39;EADDRINUSE&#39;, errno: -48, syscall: &#39;listen&#39;, address: &#39;::&#39;, port: 8080} 위와 같이 8080을 쓰려는 순간 에러가 발생하였다. 이 전에 8080 port를 사용하다가 비정상적으로 종료시킨거 같다.해결 8080 port를 사용하고 있는 프로세스의 id를 알아내야 한다. sudo lsof -i :8080 를 통해 알 수 있다. 이제 이 프로세스를 죽인다. sudo kill -9 [pid] lsof에 관하여 lsof는 list open files의 약자로 시스템에 열려있는 파일에 대한 정보를 출력해주는 명령이다. sudo yum install lsof 를 통해 설치가 가능하다 i 옵션은 IPv4로 오픈한 소켓에 대한 정보들이 나온다. 참고자료[TIL] 에러노트📕 - [Node js] address already in use[Linux] lsof 명령어 사용법" }, { "title": "Python의 immutable 객체와 mutable 객체", "url": "/posts/Python%EC%9D%98-immutable-%EA%B0%9D%EC%B2%B4%EC%99%80-mutable-%EA%B0%9D%EC%B2%B4/", "categories": "Language, Python", "tags": "python, variable", "date": "2021-09-29 02:06:00 +0900", "snippet": "💡 [[0]*3]*3과 [[0]*3 for _ in range(3)]의 차이점이 무엇일까?궁금증 코드 둘 다 [[0,0,0],[0,0,0],[0,0,0]]을 만든다. 그렇다면 어떤 차이가 있을까? [0][0]의 숫자를 1로 바꿔보자 생각대로라면 [[1,0,0],[0,0,0],[0,0,0]]이 나와야 한다. 하지만 [[0]*3]*3 의 코드로 작성한 경우 [[1,0,0],[1,0,0],[1,0,0]] 이 된다. 이유를 알아보자해결 python의 변수는 크게 immutable 객체와 mutable객체 두 가지로 나뉜다. mutable Lists Sets Dictionaries User-Defined Classes immutable Numbers(Integer, Rational, Float, Decimal, Complex &amp;amp; Booleans) Strings Tuples Frozen Sets User-Defined Classes 쉽게 설명하면 mutable은 선언후 변하는것이고 immutable은 선언 후 변하지 않는 것이다. python의 * 의 경우 복사를 의미한다. 복사할 때 mutable인 경우는 얕은 복사를 하고 immutable일 때는 깊은 복사를 한다 [0]*3은 0이 mutable이므로 깊은 복사가 일어나 값만 복사를 한다. 그렇기 때문에 주소가 각기 다른 [0,0,0] 배열이 만들어진다. 만들어진 [0,0,0]을 * 연산으로 3을 곱하면 [0,0,0]이 3개가 만들어지는데 결국 다 같은 주소를 갖는 배열이 3개가 되는것이다. python의 모든 객체는 id 함수와 is 연산자가 제공되니 이를 이용하여 직접 코딩으로 확인해보자참고Python 개념 정리 - 객체란Understanding Mutable and Immutable in Python - Great Learning" } ]
